<?xml version="1.0" ?>
<!-- =================================================================================== -->
<!-- |    This document was autogenerated by xacro from Z-Arm_10042C0_gazebo.urdf.xacro | -->
<!-- |    EDITING THIS FILE BY HAND IS NOT RECOMMENDED                                 | -->
<!-- =================================================================================== -->
<robot name="hitbot">
  <material name="aluminum">
    <color rgba="0.5 0.5 0.5 1"/>
  </material>
  <material name="plastic">
    <color rgba="0.1 0.1 0.1 1"/>
  </material>
  <link name="world"/>
  <joint name="base_joint" type="fixed">
    <origin rpy="-1.5708 0 0" xyz="0 0 0"/>
    <parent link="world"/>
    <child link="base_link"/>
  </joint>
  <link name="base_link">
    <inertial>
      <origin rpy="0 0 0" xyz="-0.0152493195612961 -0.000340773146600589 0.627217436393109"/>
      <mass value="12.1147491899625"/>
      <inertia ixx="1.57331650738548" ixy="0.00013876928001303" ixz="-0.00142621285833315" iyy="1.56540260130721" iyz="-0.00396786578401927" izz="0.0545129495020593"/>
    </inertial>
    <visual>
      <origin rpy="0 0 0" xyz="0 0 0"/>
      <geometry>
        <mesh filename="file:///home/public/hitbot_ws/install/hitbot_sim/share/hitbot_sim/meshes/Z-Arm_10042C0/base_link.dae"/>
      </geometry>
      <material name="">
        <color rgba="1 1 1 1"/>
      </material>
    </visual>
    <collision>
      <origin rpy="0 0 0" xyz="0 0 0"/>
      <geometry>
        <mesh filename="file:///home/public/hitbot_ws/install/hitbot_sim/share/hitbot_sim/meshes/Z-Arm_10042C0/base_link.dae"/>
      </geometry>
    </collision>
  </link>
  <link name="link1">
    <inertial>
      <origin rpy="0 0 0" xyz="0.0814844684502057 -0.000148613714255294 0.0317838791707967"/>
      <mass value="0.993699801386025"/>
      <inertia ixx="0.000950142292489542" ixy="-1.44578489991647E-05" ixz="7.33036655063474E-05" iyy="0.0034290254131011" iyz="-2.09106228762866E-06" izz="0.00392515031508005"/>
    </inertial>
    <visual>
      <origin rpy="0 0 0" xyz="0 0 0"/>
      <geometry>
        <mesh filename="file:///home/public/hitbot_ws/install/hitbot_sim/share/hitbot_sim/meshes/Z-Arm_10042C0/link1.dae"/>
      </geometry>
      <material name="">
        <color rgba="0.792156862745098 0.819607843137255 0.933333333333333 1"/>
      </material>
    </visual>
    <collision>
      <origin rpy="0 0 0" xyz="0 0 0"/>
      <geometry>
        <mesh filename="file:///home/public/hitbot_ws/install/hitbot_sim/share/hitbot_sim/meshes/Z-Arm_10042C0/link1.dae"/>
      </geometry>
    </collision>
  </link>
  <joint name="joint1" type="prismatic">
    <!-- <origin
      xyz="0 -0.78099 0"
      rpy="1.5708 0 0" /> -->
    <origin rpy="1.5708 0 0" xyz="0 -1.2 0"/>
    <parent link="base_link"/>
    <child link="link1"/>
    <axis xyz="0 0 1"/>
    <limit effort="1" lower="-0.95" upper="0" velocity="1"/>
  </joint>
  <link name="link2">
    <inertial>
      <origin rpy="0 0 0" xyz="0.111045959309931 2.43604684770394E-05 -0.0314379854113542"/>
      <mass value="0.085844227294122"/>
      <inertia ixx="0.00708782289991147" ixy="7.1034720884927E-06" ixz="0.000255328408086295" iyy="0.0470616581346809" iyz="3.5236472788361E-07" izz="0.0503399714879645"/>
    </inertial>
    <visual>
      <origin rpy="0 0 0" xyz="0 0 0"/>
      <geometry>
        <mesh filename="file:///home/public/hitbot_ws/install/hitbot_sim/share/hitbot_sim/meshes/Z-Arm_10042C0/link2.dae"/>
      </geometry>
      <material name="">
        <color rgba="1 1 1 1"/>
      </material>
    </visual>
    <collision>
      <origin rpy="0 0 0" xyz="0 0 0"/>
      <geometry>
        <mesh filename="file:///home/public/hitbot_ws/install/hitbot_sim/share/hitbot_sim/meshes/Z-Arm_10042C0/link2.dae"/>
      </geometry>
    </collision>
  </link>
  <joint name="joint2" type="revolute">
    <origin rpy="0 0 0" xyz="0.133 0 0"/>
    <parent link="link1"/>
    <child link="link2"/>
    <axis xyz="0 0 1"/>
    <limit effort="30" lower="-1.571" upper="1.571" velocity="1.571"/>
  </joint>
  <link name="link3">
    <inertial>
      <origin rpy="0 0 0" xyz="0.0953068068304957 1.45953948384313E-13 -0.0226655447402296"/>
      <mass value="0.0343252725336984"/>
      <inertia ixx="0.00328366639192851" ixy="-1.56304791044749E-14" ixz="5.94905284720721E-05" iyy="0.0233302625835159" iyz="1.47845983740584E-16" izz="0.0254348240065591"/>
    </inertial>
    <visual>
      <origin rpy="0 0 0" xyz="0 0 0"/>
      <geometry>
        <mesh filename="file:///home/public/hitbot_ws/install/hitbot_sim/share/hitbot_sim/meshes/Z-Arm_10042C0/link3.dae"/>
      </geometry>
      <material name="">
        <color rgba="1 1 1 1"/>
      </material>
    </visual>
    <collision>
      <origin rpy="0 0 0" xyz="0 0 0"/>
      <geometry>
        <mesh filename="file:///home/public/hitbot_ws/install/hitbot_sim/share/hitbot_sim/meshes/Z-Arm_10042C0/link3.dae"/>
      </geometry>
    </collision>
  </link>
  <joint name="joint3" type="revolute">
    <origin rpy="0 0 0" xyz="0.22 0 -0.06799"/>
    <parent link="link2"/>
    <child link="link3"/>
    <axis xyz="0 0 1"/>
    <limit effort="30" lower="-2.967" upper="2.967" velocity="1.571"/>
  </joint>
  <link name="link4">
    <inertial>
      <origin rpy="0 0 0" xyz="-0.000247759291386207 -7.08258575587396E-12 -0.0209527102025886"/>
      <mass value="0.0120587662892703"/>
      <inertia ixx="5.0401439482025E-05" ixy="1.41751614431463E-14" ixz="-1.42422376690236E-07" iyy="5.01231671450723E-05" iyz="8.96921067460828E-15" izz="8.90018861873181E-05"/>
    </inertial>
    <visual>
      <origin rpy="0 0 0" xyz="0 0 0"/>
      <geometry>
        <mesh filename="file:///home/public/hitbot_ws/install/hitbot_sim/share/hitbot_sim/meshes/Z-Arm_10042C0/link4.dae"/>
      </geometry>
      <material name="">
        <color rgba="1 1 1 1"/>
      </material>
    </visual>
    <collision>
      <origin rpy="0 0 0" xyz="0 0 0"/>
      <geometry>
        <mesh filename="file:///home/public/hitbot_ws/install/hitbot_sim/share/hitbot_sim/meshes/Z-Arm_10042C0/link4.dae"/>
      </geometry>
    </collision>
  </link>
  <joint name="joint4" type="revolute">
    <origin rpy="0 0 3.1416" xyz="0.2 0 -0.0284"/>
    <parent link="link3"/>
    <child link="link4"/>
    <axis xyz="0 0 1"/>
    <limit effort="30" lower="-18.850" upper="18.850" velocity="1.571"/>
  </joint>
  <!-- camera body, with origin at bottom screw mount -->
  <joint name="camera_1_joint" type="fixed">
    <origin rpy="0 0 0" xyz="0.125 0.0 0.07"/>
    <parent link="link1"/>
    <child link="camera_1_bottom_screw_frame"/>
  </joint>
  <link name="camera_1_bottom_screw_frame"/>
  <joint name="camera_1_link_joint" type="fixed">
    <origin rpy="0 0 0" xyz="0.011150000000000002 0.0475 0.0145"/>
    <parent link="camera_1_bottom_screw_frame"/>
    <child link="camera_1_link"/>
  </joint>
  <link name="camera_1_link">
    <visual>
      <!-- the mesh origin is at front plate in between the two infrared camera axes -->
      <!-- <origin xyz="${d455_zero_depth_to_glass-d455_cam_depth/2} ${-d455_cam_depth_py} 0" rpy="0 0 0"/> -->
      <origin rpy="1.5707963267948966 0 1.5707963267948966" xyz="0.0046500000000000005 -0.0475 0"/>
      <geometry>
        <!-- <box size="${d455_cam_depth} ${d455_cam_width} ${d455_cam_height}"/> -->
        <mesh filename="file:///opt/ros/humble/share/realsense2_description/meshes/d435.dae"/>
      </geometry>
      <material name="aluminum"/>
    </visual>
    <collision>
      <origin rpy="0 0 0" xyz="-0.00845 -0.0475 0"/>
      <geometry>
        <box size="0.026 0.124 0.029"/>
      </geometry>
    </collision>
    <inertial>
      <!-- The following are not reliable values, and should not be used for modeling -->
      <mass value="0.072"/>
      <origin xyz="0 0 0"/>
      <inertia ixx="0.003881243" ixy="0.0" ixz="0.0" iyy="0.000498940" iyz="0.0" izz="0.003879257"/>
    </inertial>
  </link>
  <!-- camera depth joints and links -->
  <joint name="camera_1_depth_joint" type="fixed">
    <origin rpy="0 0 0" xyz="0 0 0"/>
    <parent link="camera_1_link"/>
    <child link="camera_1_depth_frame"/>
  </joint>
  <link name="camera_1_depth_frame"/>
  <joint name="camera_1_depth_optical_joint" type="fixed">
    <origin rpy="-1.5707963267948966 0 -1.5707963267948966" xyz="0 0 0"/>
    <parent link="camera_1_depth_frame"/>
    <child link="camera_1_depth_optical_frame"/>
  </joint>
  <link name="camera_1_depth_optical_frame"/>
  <!-- camera left IR joints and links -->
  <joint name="camera_1_infra1_joint" type="fixed">
    <origin rpy="0 0 0" xyz="0 0.0 0"/>
    <parent link="camera_1_link"/>
    <child link="camera_1_infra1_frame"/>
  </joint>
  <link name="camera_1_infra1_frame"/>
  <joint name="camera_1_infra1_optical_joint" type="fixed">
    <origin rpy="-1.5707963267948966 0 -1.5707963267948966" xyz="0 0 0"/>
    <parent link="camera_1_infra1_frame"/>
    <child link="camera_1_infra1_optical_frame"/>
  </joint>
  <link name="camera_1_infra1_optical_frame"/>
  <!-- camera right IR joints and links -->
  <joint name="camera_1_infra2_joint" type="fixed">
    <origin rpy="0 0 0" xyz="0 -0.095 0"/>
    <parent link="camera_1_link"/>
    <child link="camera_1_infra2_frame"/>
  </joint>
  <link name="camera_1_infra2_frame"/>
  <joint name="camera_1_infra2_optical_joint" type="fixed">
    <origin rpy="-1.5707963267948966 0 -1.5707963267948966" xyz="0 0 0"/>
    <parent link="camera_1_infra2_frame"/>
    <child link="camera_1_infra2_optical_frame"/>
  </joint>
  <link name="camera_1_infra2_optical_frame"/>
  <!-- camera color joints and links -->
  <joint name="camera_1_color_joint" type="fixed">
    <origin rpy="0 0 0" xyz="0 -0.059 0"/>
    <parent link="camera_1_link"/>
    <child link="camera_1_color_frame"/>
  </joint>
  <link name="camera_1_color_frame"/>
  <joint name="camera_1_color_optical_joint" type="fixed">
    <origin rpy="-1.5707963267948966 0 -1.5707963267948966" xyz="0 0 0"/>
    <parent link="camera_1_color_frame"/>
    <child link="camera_1_color_optical_frame"/>
  </joint>
  <link name="camera_1_color_optical_frame"/>
  <link name="camera_1_accel_frame"/>
  <link name="camera_1_accel_optical_frame"/>
  <link name="camera_1_gyro_frame"/>
  <link name="camera_1_gyro_optical_frame"/>
  <link name="camera_1_imu_optical_frame"/>
  <joint name="camera_1_accel_joint" type="fixed">
    <origin rpy="0 0 0" xyz="-0.01602 -0.03022 0.0074"/>
    <parent link="camera_1_link"/>
    <child link="camera_1_accel_frame"/>
  </joint>
  <joint name="camera_1_accel_optical_joint" type="fixed">
    <origin rpy="-1.5707963267948966 0 -1.5707963267948966" xyz="0 0 0"/>
    <parent link="camera_1_accel_frame"/>
    <child link="camera_1_accel_optical_frame"/>
  </joint>
  <joint name="camera_1_gyro_joint" type="fixed">
    <origin rpy="0 0 0" xyz="-0.01602 -0.03022 0.0074"/>
    <parent link="camera_1_link"/>
    <child link="camera_1_gyro_frame"/>
  </joint>
  <joint name="camera_1_gyro_optical_joint" type="fixed">
    <origin rpy="-1.5707963267948966 0 -1.5707963267948966" xyz="0 0 0"/>
    <parent link="camera_1_gyro_frame"/>
    <child link="camera_1_gyro_optical_frame"/>
  </joint>
  <joint name="camera_1_imu_optical_joint" type="fixed">
    <origin rpy="0 0 0" xyz="0 0 0"/>
    <parent link="camera_1_gyro_optical_frame"/>
    <child link="camera_1_imu_optical_frame"/>
  </joint>
  
</robot>
